This is your first time running this script. Enter the following information to get going!

Enter your Public Address: 
Traceback (most recent call last):
  File "./pydeepool.py", line 340, in <module>
    with open('config.json', 'r') as f:
FileNotFoundError: [Errno 2] No such file or directory: 'config.json'

During handling of the above exception, another exception occurred:

Traceback (most recent call last):
  File "./pydeepool.py", line 344, in <module>
    address = input()
OSError: [Errno 9] Bad file descriptor
This is your first time running this script. Enter the following information to get going!

Enter your Public Address: 
Traceback (most recent call last):
  File "./pydeepool.py", line 340, in <module>
    with open('config.json', 'r') as f:
FileNotFoundError: [Errno 2] No such file or directory: 'config.json'

During handling of the above exception, another exception occurred:

Traceback (most recent call last):
  File "./pydeepool.py", line 344, in <module>
    address = input()
OSError: [Errno 9] Bad file descriptor

	Voters Share: 80%
	Public Pool: True
	Minimum Payout: 1 Rise.
	Account 3511748430431975976R
	Key f4307b1f23630776dc621302ad45cee063bffc4140de00a501c85d6d3abeb980

Starting at block height 359535
Traceback (most recent call last):
  File "./pydeepool.py", line 460, in <module>
    process_blocks(start)
  File "./pydeepool.py", line 208, in process_blocks
    time.sleep(max(0, pulse))
KeyboardInterrupt
ERROR:tornado.application:Uncaught exception GET /addr/8813920139577420006R/ (50.67.63.7)
HTTPServerRequest(protocol='http', host='risescanner.com:8989', method='GET', uri='/addr/8813920139577420006R/', version='HTTP/1.1', remote_ip='50.67.63.7', headers={'Connection': 'keep-alive', 'If-None-Match': '"1ab723a318fa00f0e4c713b5dbdca30103070c99"', 'X-Requested-With': 'XMLHttpRequest', 'Referer': 'http://risescanner.com:8989/', 'Accept': '*/*', 'Cookie': 'csrftoken=azG5Hts1GNuFaFVoL5COm2BBZfdmxueciLKHV0di92gndv79Uxu9nlPh1wJ7wfJd', 'User-Agent': 'Mozilla/5.0 (Windows NT 10.0; Win64; x64) AppleWebKit/537.36 (KHTML, like Gecko) Chrome/61.0.3163.100 Safari/537.36', 'Accept-Language': 'en-US,en;q=0.8', 'Host': 'risescanner.com:8989', 'Accept-Encoding': 'gzip, deflate'})
Traceback (most recent call last):
  File "/home/aaron/.local/lib/python3.5/site-packages/peewee.py", line 3220, in get
    return next(clone.execute())
  File "/home/aaron/.local/lib/python3.5/site-packages/peewee.py", line 2363, in next
    obj = self.iterate()
  File "/home/aaron/.local/lib/python3.5/site-packages/peewee.py", line 2345, in iterate
    raise StopIteration
StopIteration

During handling of the above exception, another exception occurred:

Traceback (most recent call last):
  File "/home/aaron/.local/lib/python3.5/site-packages/tornado/web.py", line 1509, in _execute
    result = method(*self.path_args, **self.path_kwargs)
  File "/home/aaron/github/PyDeePool/website.py", line 52, in get
    context['voter'] = Voter.get(address=addr)
  File "/home/aaron/.local/lib/python3.5/site-packages/peewee.py", line 4988, in get
    return sq.get()
  File "/home/aaron/.local/lib/python3.5/site-packages/peewee.py", line 3224, in get
    % self.sql())
pydeepool.VoterDoesNotExist: Instance matching query does not exist:
SQL: SELECT "t1"."id", "t1"."joined", "t1"."payout", "t1"."total_paid", "t1"."current_ave", "t1"."address" FROM "voter" AS t1 WHERE ("t1"."address" = ?)
PARAMS: ['8813920139577420006R']
ERROR:tornado.access:500 GET /addr/8813920139577420006R/ (50.67.63.7) 39.36ms
ERROR:tornado.application:Uncaught exception GET /addr/8813920139577420006R/ (50.67.63.7)
HTTPServerRequest(protocol='http', host='risescanner.com:8989', method='GET', uri='/addr/8813920139577420006R/', version='HTTP/1.1', remote_ip='50.67.63.7', headers={'Cookie': 'csrftoken=azG5Hts1GNuFaFVoL5COm2BBZfdmxueciLKHV0di92gndv79Uxu9nlPh1wJ7wfJd', 'Accept': '*/*', 'Referer': 'http://risescanner.com:8989/', 'User-Agent': 'Mozilla/5.0 (Windows NT 10.0; Win64; x64) AppleWebKit/537.36 (KHTML, like Gecko) Chrome/61.0.3163.100 Safari/537.36', 'Accept-Encoding': 'gzip, deflate', 'Host': 'risescanner.com:8989', 'Accept-Language': 'en-US,en;q=0.8', 'X-Requested-With': 'XMLHttpRequest', 'Connection': 'keep-alive'})
Traceback (most recent call last):
  File "/home/aaron/.local/lib/python3.5/site-packages/peewee.py", line 3220, in get
    return next(clone.execute())
  File "/home/aaron/.local/lib/python3.5/site-packages/peewee.py", line 2363, in next
    obj = self.iterate()
  File "/home/aaron/.local/lib/python3.5/site-packages/peewee.py", line 2345, in iterate
    raise StopIteration
StopIteration

During handling of the above exception, another exception occurred:

Traceback (most recent call last):
  File "/home/aaron/.local/lib/python3.5/site-packages/tornado/web.py", line 1509, in _execute
    result = method(*self.path_args, **self.path_kwargs)
  File "/home/aaron/github/PyDeePool/website.py", line 52, in get
    context['voter'] = Voter.get(address=addr)
  File "/home/aaron/.local/lib/python3.5/site-packages/peewee.py", line 4988, in get
    return sq.get()
  File "/home/aaron/.local/lib/python3.5/site-packages/peewee.py", line 3224, in get
    % self.sql())
pydeepool.VoterDoesNotExist: Instance matching query does not exist:
SQL: SELECT "t1"."id", "t1"."joined", "t1"."payout", "t1"."total_paid", "t1"."current_ave", "t1"."address" FROM "voter" AS t1 WHERE ("t1"."address" = ?)
PARAMS: ['8813920139577420006R']
ERROR:tornado.access:500 GET /addr/8813920139577420006R/ (50.67.63.7) 31.80ms
